[ 2024-03-17 14:19:25,420 ] 160 numexpr.utils - INFO - NumExpr defaulting to 4 threads.
[ 2024-03-17 14:19:53,246 ] 5 root - INFO - Entered the data ingestion method or component
[ 2024-03-17 14:19:53,263 ] 8 root - INFO - Read the dataset as dataframe
[ 2024-03-17 14:19:53,271 ] 11 root - INFO - Train test split initiated
[ 2024-03-17 14:19:53,282 ] 15 root - INFO - Ingestion of the data is completed
[ 2024-03-17 14:19:53,308 ] 418 root - INFO - Read train and test data completed
[ 2024-03-17 14:19:53,308 ] 419 root - INFO - Obtaining preprocessing object
[ 2024-03-17 14:19:53,308 ] 404 root - INFO - Categorical columns: ['gender', 'incident_type', 'collision_type', 'incident_severity', 'incident_city', 'incident_hour_of_the_day', 'police_report_available', 'auto_make', 'auto_model', 'auto_year']
[ 2024-03-17 14:19:53,308 ] 405 root - INFO - Numerical columns: ['age', 'number_of_vehicles_involved', 'witnesses', 'vehicle_claim']
[ 2024-03-17 14:19:53,310 ] 426 root - INFO - Applying preprocessing object on training dataframe and testing dataframe.
[ 2024-03-17 14:20:19,396 ] 15 root - ERROR - An error occurred: Error occured in python script name [<stdin>] line number [44] error message[[Errno 2] No such file or directory: '../../artifacts/train.csv']
Traceback (most recent call last):
  File "<stdin>", line 44, in initiate_data_transformation
  File "C:\Users\FOLASADE\anaconda3\Lib\site-packages\pandas\io\parsers\readers.py", line 912, in read_csv
    return _read(filepath_or_buffer, kwds)
           ^^^^^^^^^^^^^^^^^^^^^^^^^^^^^^^
  File "C:\Users\FOLASADE\anaconda3\Lib\site-packages\pandas\io\parsers\readers.py", line 577, in _read
    parser = TextFileReader(filepath_or_buffer, **kwds)
             ^^^^^^^^^^^^^^^^^^^^^^^^^^^^^^^^^^^^^^^^^^
  File "C:\Users\FOLASADE\anaconda3\Lib\site-packages\pandas\io\parsers\readers.py", line 1407, in __init__
    self._engine = self._make_engine(f, self.engine)
                   ^^^^^^^^^^^^^^^^^^^^^^^^^^^^^^^^^
  File "C:\Users\FOLASADE\anaconda3\Lib\site-packages\pandas\io\parsers\readers.py", line 1661, in _make_engine
    self.handles = get_handle(
                   ^^^^^^^^^^^
  File "C:\Users\FOLASADE\anaconda3\Lib\site-packages\pandas\io\common.py", line 859, in get_handle
    handle = open(
             ^^^^^
FileNotFoundError: [Errno 2] No such file or directory: '../../artifacts/train.csv'

During handling of the above exception, another exception occurred:

Traceback (most recent call last):
  File "<stdin>", line 9, in <module>
  File "<stdin>", line 64, in initiate_data_transformation
src.exception.CustomException: Error occured in python script name [<stdin>] line number [44] error message[[Errno 2] No such file or directory: '../../artifacts/train.csv']
[ 2024-03-17 14:34:36,147 ] 15 root - ERROR - Custom exception occurred: Error occured in python script name [<stdin>] line number [45] error message[Train file not found at: ../../artifacts/train.csv]
