[ 2024-03-17 13:18:16,050 ] 160 numexpr.utils - INFO - NumExpr defaulting to 4 threads.
[ 2024-03-17 13:18:20,110 ] 5 root - INFO - Entered the data ingestion method or component
[ 2024-03-17 13:18:20,144 ] 8 root - INFO - Read the dataset as dataframe
[ 2024-03-17 13:18:20,147 ] 11 root - INFO - Train test split initiated
[ 2024-03-17 13:18:20,159 ] 15 root - INFO - Ingestion of the data is completed
[ 2024-03-17 13:18:20,173 ] 92 root - INFO - Read train and test data completed
[ 2024-03-17 13:18:20,173 ] 94 root - INFO - Obtaining preprocessing object
[ 2024-03-17 13:18:20,173 ] 68 root - INFO - Categorical columns: ['gender', 'incident_type', 'collision_type', 'incident_severity', 'incident_city', 'incident_hour_of_the_day', 'police_report_available', 'auto_make', 'auto_model', 'auto_year']
[ 2024-03-17 13:18:20,173 ] 69 root - INFO - Numerical columns: ['age', 'number_of_vehicles_involved', 'witnesses', 'vehicle_claim']
[ 2024-03-17 13:18:20,188 ] 111 root - INFO - Applying preprocessing object on training dataframe and testing dataframe.
[ 2024-03-17 14:11:50,942 ] 15 root - ERROR - An error occurred: Error occured in python script name [<stdin>] line number [44] error message[[Errno 2] No such file or directory: '../../artifacts/train.csv']
Traceback (most recent call last):
  File "<stdin>", line 44, in initiate_data_transformation
  File "C:\Users\FOLASADE\anaconda3\Lib\site-packages\pandas\io\parsers\readers.py", line 912, in read_csv
    return _read(filepath_or_buffer, kwds)
           ^^^^^^^^^^^^^^^^^^^^^^^^^^^^^^^
  File "C:\Users\FOLASADE\anaconda3\Lib\site-packages\pandas\io\parsers\readers.py", line 577, in _read
    parser = TextFileReader(filepath_or_buffer, **kwds)
             ^^^^^^^^^^^^^^^^^^^^^^^^^^^^^^^^^^^^^^^^^^
  File "C:\Users\FOLASADE\anaconda3\Lib\site-packages\pandas\io\parsers\readers.py", line 1407, in __init__
    self._engine = self._make_engine(f, self.engine)
                   ^^^^^^^^^^^^^^^^^^^^^^^^^^^^^^^^^
  File "C:\Users\FOLASADE\anaconda3\Lib\site-packages\pandas\io\parsers\readers.py", line 1661, in _make_engine
    self.handles = get_handle(
                   ^^^^^^^^^^^
  File "C:\Users\FOLASADE\anaconda3\Lib\site-packages\pandas\io\common.py", line 859, in get_handle
    handle = open(
             ^^^^^
FileNotFoundError: [Errno 2] No such file or directory: '../../artifacts/train.csv'

During handling of the above exception, another exception occurred:

Traceback (most recent call last):
  File "<stdin>", line 9, in <module>
  File "<stdin>", line 64, in initiate_data_transformation
src.exception.CustomException: Error occured in python script name [<stdin>] line number [44] error message[[Errno 2] No such file or directory: '../../artifacts/train.csv']
[ 2024-03-17 14:12:17,004 ] 15 root - ERROR - An error occurred: Error occured in python script name [<stdin>] line number [44] error message[[Errno 2] No such file or directory: '../../artifacts/train.csv']
Traceback (most recent call last):
  File "<stdin>", line 44, in initiate_data_transformation
  File "C:\Users\FOLASADE\anaconda3\Lib\site-packages\pandas\io\parsers\readers.py", line 912, in read_csv
    return _read(filepath_or_buffer, kwds)
           ^^^^^^^^^^^^^^^^^^^^^^^^^^^^^^^
  File "C:\Users\FOLASADE\anaconda3\Lib\site-packages\pandas\io\parsers\readers.py", line 577, in _read
    parser = TextFileReader(filepath_or_buffer, **kwds)
             ^^^^^^^^^^^^^^^^^^^^^^^^^^^^^^^^^^^^^^^^^^
  File "C:\Users\FOLASADE\anaconda3\Lib\site-packages\pandas\io\parsers\readers.py", line 1407, in __init__
    self._engine = self._make_engine(f, self.engine)
                   ^^^^^^^^^^^^^^^^^^^^^^^^^^^^^^^^^
  File "C:\Users\FOLASADE\anaconda3\Lib\site-packages\pandas\io\parsers\readers.py", line 1661, in _make_engine
    self.handles = get_handle(
                   ^^^^^^^^^^^
  File "C:\Users\FOLASADE\anaconda3\Lib\site-packages\pandas\io\common.py", line 859, in get_handle
    handle = open(
             ^^^^^
FileNotFoundError: [Errno 2] No such file or directory: '../../artifacts/train.csv'

During handling of the above exception, another exception occurred:

Traceback (most recent call last):
  File "<stdin>", line 9, in <module>
  File "<stdin>", line 64, in initiate_data_transformation
src.exception.CustomException: Error occured in python script name [<stdin>] line number [44] error message[[Errno 2] No such file or directory: '../../artifacts/train.csv']
